Workbook

Sheet Database_Index2
A1: Parameter | B1: Data Point1 | C1: Data Point2 | D1: Data Point3 | E1: Data Point4 | F1: Data Point5 | G1: Data Point6 | H1: Data Point7 | I1: Data Point8 | J1: Data Point9 | K1: Data Point10
A2: CABLEPULL | B2: Material | C2: Phase | D2: Test | E2: Section Width | F2: Ampacity | G2: Structure Depth | H2: Assembly Drawing
A3: CABLEPULL-2 | B3: Material | C3: Phase | D3: Test | E3: Section Width | F3: Ampacity | G3: Structure Depth | H3: Assembly Drawing
A4: AUXMACON | B4: Minimum Structure Depth | C4: Cross Bus Position | D4: Phase | E4: Test | F4: Material | G4: Device
A5: SAUXMACO | B5: Structure Depth | C5: Structure Width | D5: Cross Bus Position | E5: Test | F5: Aux X-Bus Hole CTRS | G5: Material | H5: Device
A6: WCCONNMD | B6: Assembly Number | C6: Test | D6: Material | E6: Device
A7: MDCONLN | B7: Minimum Structure Depth | C7: Minimum Structure Depth | D7: Bus Position | E7: DWG No. | F7: Test | G7: Material | H7: Device
A8: MDCONLOA | B8: Minimum Structure Depth | C8: Bus Position | D8: DWG No. | E8: Test | F8: Structure Depth | G8: Material | H8: Device | I8: Support Edge to Edge
A9: SMDCONLN | B9: DWG No. | C9: Structure Depth | D9: Cross Bus Position | E9: Heat Test | F9: Amp per Sq CU and Alum
A10: STMNCHCO | B10: DWG No. | C10: Heat Test | D10: Amp per Sq CU and Alum | F10: 36/45W
A11: PHASECONN | B11: Width | C11: Assembly Drawing | D11: Density | E11: Material | F11: Amperage | G11: Device
A12: AUXILCB | B12: Amperage | C12: Width (Wide) | D12: Test | E12: Assembly Number | F12: 3/1/ Neutral Phase Cross Bus
A13: AUXMACB | B13: DWG Number | C13: Structure Width | D13: Test | E13: Material | F13: Amperage | G13: Bus Hole Center | H13: Phase
A14: MAINCB | B14: DWG No. | C14: Bus Hole Center | D14: Amperage | E14: Test | F14: Structure Width | G14: Material | H14: Mounting/Non-Mounting Assemblies
A15: DISTCB | B15: Amperage | C15: Structure Width | D15: Test | E15: Material | F15: Assembly No.
A16: BUSCENTE | B16: Bus Rating | C16: Device Centers | D16: X-Bus Centers | E16: Structure Width | F16: Device
A17: SWBDBUS | B17: -
A18: GENRISERS | B18: Amperage | C18: Material | D18: Test | E18: Phase | F18: Bus Centers
A19: GENXBUS | B19: Bus Centers | C19: Amperage | D19: Test | E19: Material
A20: GENDCLMTA | B20: Bus Centers | C20: Test | D20: Material | E20: Phase | F20: Device Type | G20: Amperage
A21: GENDCLMBS | B21: Device Type | C21: Bus Center | D21: Family Numbers/ Assembly no. | E21: Test | F21: Material | G21: Phase
A22: GENDCUMTA | B22: Device Type | C22: Bus Centers | D22: Family Numbers/ Assembly no. | E22: Test | F22: Material | G22: Phase
A23: GENDCUMTS | B23: Device Type | C23: Bus Center | D23: Family Numbers/ Assembly no. | E23: Test | F23: Material | G23: Phase
A24: GENDRLMTA | B24: Device Type | C24: Bus Center | D24: Family Numbers/ Assembly no. | E24: Test | F24: Material | G24: Phase
A25: GENDRLMBS | B25: Device Type | C25: Bus Center | D25: Family Numbers/ Assembly no. | E25: Test | F25: Material | G25: Phase
A26: GENDRUMTA | B26: Device Type | C26: Bus Center | D26: Family Numbers/ Assembly no. | E26: Test | F26: Material | G26: Phase
A27: GENDRUMTS | B27: Device Type | C27: Bus Center | D27: Family Numbers/ Assembly no. | E27: Test | F27: Material | G27: Phase
A28: GENNEUTRALXBUS | B28: Width (Wide) | C28: Amperage | D28: Test | E28: Material | F28: Assembly No.
A29: GENNEUTLUGPADS | B29: Device Type | C29: Width (Wide) | D29: Bus Center | E29: Disconnect | F29: Assembly No. | G29: Test | H29: Material | I29: Service/Non-Service Entrance
A30: GNDBUS | B30: Bus Rating | C30: Structure Width | D30: Amperage | E30: Material | F30: Assembly No. | G30: Utility
A31: GNBUSPLI | B31: Amperage | C31: Bus Capacity | D31: Material | E31: Assembly No. | F31: Offset/ Gnd Bus Splices
A32: GND BOND | B32: Amperage | C32: Assembly No. | D32: Material
A33: DISECNEU-1 | B33: Riser Amperage Rating | C33: Assembly No. | D33: Test | E33: Material | F33: Width (Wide) | G33: Cross Neut Rating
A34: FAFANEU | B34: Ameperage | C34: Width (Wide) | D34: Test | E34: Material | F34: Assembly No. | G34: Neutral Lugs
A35: NEUGFS | B35: Assembly No. | C35: Material | D35: X-Bus/Chassis Amperage
A36: MASECNEUT | B36: Riser Amperage Rating | C36: Assembly No. | D36: Width (Wide) | E36: Test | F36: Material | G36: Cross Neut Rating | H36: Device
A37: IMSECNEUT | B37: Breaker Type | C37: Max Breaker Amperage | D37: Assembly No. | E37: Cable Entry | F37: Service Entrance | G37: Ground Fault Protection | H37: Bus Position | I37: Test | J37: Material | K37: Width (Wide)
A38: SELNEUT | B38: Assembly No. | C38: Width (Wide) | D38: Test | E38: Material | F38: Device and Amp Rating
A39: RVMNNEUT | B39: Assembly No. | C39: Width (Wide) | D39: Test | E39: Amperage
A40: BUSSPLIC | B40: Assembly No. | C40: Material | D40: Bus Size | E40: Splice Offset | F40: Test
...

Sheet Extracted_Parameters
A1: Unique Parameters | B1: Current Extraction Coverage
A2: Material | B2: Material
A3: Minimum Structure Depth | B3: Structure Depth
A4: Structure Depth | B4: Assembly No.
A5: Assembly Number | B5: Width
A6: DWG No. | B6: Amperage
A7: Amperage | B7: Depth
A8: Bus Rating | B8: Bus Rating
A9: Bus Centers | B9: Height
A10: Device Type | B10: Voltage
A11: Width (Wide) | B11: 3/1 Phase
A12: Riser Amperage Rating | B12: 3/4 Wire
... A31: Description | B31: Width (Wide)
A32: Socket Type
A33: Utility Name
A34: Height
A35: Breaker Name
A36: 3/1 Phase
A37: Utility Compartment Type
A38: Utility Amperage
A39: With/ Without Lugs
A40: Lugs and Pressbolts/Pressbolts only
A41: Switch Catalog No.
A42: Application B/C
A43: Phase
... A229: Pressbolts only/ Pressbolts and Lugs

Sheet MCOE Checklist
N1: Possiblity Analysis | O1: Non-Available Parameters
A2: Bus-Cable Pull, Non Utility Specific | B2: CABLEPULL | C2: Material | D2: 3/1 Phase | E2: Heat Test/Density | F2: Section Width | G2: Amperage | H2: Multiple Sheets | I2: Assembly No. | N2: {=SUMPRODUCT(--ISNUMBER(MATCH(TRIM(C2:L2),Extracted_Parameters!$B:$B,0)))=COUNTA(C2:K2)} -> FALSE | O2: {=COUNTA(C2:K2)-SUMPRODUCT(--ISNUMBER(MATCH(C2:K2,Extracted_Parameters!$B:$B,0)))} -> 1
B3: CABLEPULL-2 | C3: Material | D3: 3/1 Phase | E3: Heat Test/Density | F3: Section Width | G3: Amperage | H3: Multiple Sheets | N3: {=SUMPRODUCT(--ISNUMBER(MATCH(TRIM(C3:L3),Extracted_Parameters!$B:$B,0)))=COUNTA(C3:K3)} -> FALSE | O3: {=COUNTA(C3:K3)-SUMPRODUCT(--ISNUMBER(MATCH(C3:K3,Extracted_Parameters!$B:$B,0)))} -> 1
A4: Bus-Connectors, Top of Device to Upper (Auxiliary) Cross Bus | B4: AUXMACON | C4: Minimum Structure Depth | D4: Cross Bus Position | E4: 3/1 Phase (3/1) | F4: Heat Test/Density | G4: Material | H4: Device | N4: {=SUMPRODUCT(--ISNUMBER(MATCH(TRIM(C4:L4),Extracted_Parameters!$B:$B,0)))=COUNTA(C4:K4)} -> FALSE | O4: {=COUNTA(C4:K4)-SUMPRODUCT(--ISNUMBER(MATCH(C4:K4,Extracted_Parameters!$B:$B,0)))} -> 4
B5: SAUXMACO | C5: Structure Depth | D5: Width (Wide) | E5: Cross Bus Position | F5: Heat Test/Density | G5: Aux X-Bus Hole CTRS | H5: Material | I5: Device | N5: {=SUMPRODUCT(--ISNUMBER(MATCH(TRIM(C5:L5),Extracted_Parameters!$B:$B,0)))=COUNTA(C5:K5)} -> FALSE | O5: {=COUNTA(C5:K5)-SUMPRODUCT(--ISNUMBER(MATCH(C5:K5,Extracted_Parameters!$B:$B,0)))} -> 3 | R5: Non-Available Datapoints | S5: Total List of Parameters | T5: Percentage of Total
B6: WCCONNMD | C6: Assembly No. | D6: Heat Test/Density | E6: Material | F6: Device | N6: {=SUMPRODUCT(--ISNUMBER(MATCH(TRIM(C6:L6),Extracted_Parameters!$B:$B,0)))=COUNTA(C6:K6)} -> FALSE | O6: {=COUNTA(C6:K6)-SUMPRODUCT(--ISNUMBER(MATCH(C6:K6,Extracted_Parameters!$B:$B,0)))} -> 1 | R6: 0 | S6: =COUNTIF($O$2:$O$260,R6) -> 64 | T6: =(S6/COUNT($O$2:$O$260))*100 -> 27.004219
A7: Bus-Connectors, Device to Lower (Standard) Cross Bus | B7: MDCONLN | C7: Minimum Structure Depth | D7: Minimum Structure Depth | E7: Bus Position | F7: DWG No. | G7: Heat Test/Density | H7: Material | I7: Device | N7: {=SUMPRODUCT(--ISNUMBER(MATCH(TRIM(C7:L7),Extracted_Parameters!$B:$B,0)))=COUNTA(C7:K7)} -> FALSE | O7: {=COUNTA(C7:K7)-SUMPRODUCT(--ISNUMBER(MATCH(C7:K7,Extracted_Parameters!$B:$B,0)))} -> 4 | R7: 1 | S7: =COUNTIF($O$2:$O$260,R7) -> 68 | T7: =(S7/COUNT($O$2:$O$260))*100 -> 28.691983
B8: MDCONLOA | C8: Minimum Structure Depth | D8: Bus Position | E8: DWG No. | F8: Heat Test/Density | G8: Structure Depth | H8: Material | I8: Device | J8: Support Edge to Edge | N8: {=SUMPRODUCT(--ISNUMBER(MATCH(TRIM(C8:L8),Extracted_Parameters!$B:$B,0)))=COUNTA(C8:K8)} -> FALSE | O8: {=COUNTA(C8:K8)-SUMPRODUCT(--ISNUMBER(MATCH(C8:K8,Extracted_Parameters!$B:$B,0)))} -> 4 | R8: 2 | S8: =COUNTIF($O$2:$O$260,R8) -> 52 | T8: =(S8/COUNT($O$2:$O$260))*100 -> 21.940928
B9: SMDCONLN | C9: DWG No. | D9: Structure Depth | E9: Cross Bus Position | F9: Heat Test | G9: Amp per Sq CU and Alum | N9: {=SUMPRODUCT(--ISNUMBER(MATCH(TRIM(C9:L9),Extracted_Parameters!$B:$B,0)))=COUNTA(C9:K9)} -> FALSE | O9: {=COUNTA(C9:K9)-SUMPRODUCT(--ISNUMBER(MATCH(C9:K9,Extracted_Parameters!$B:$B,0)))} -> 4 | R9: 3 | S9: =COUNTIF($O$2:$O$260,R9) -> 36 | T9: =(S9/COUNT($O$2:$O$260))*100 -> 15.189873
B10: STMNCHCO | C10: DWG No. | D10: Heat Test | E10: Amp per Sq CU and Alum | G10: 36/45W | N10: {=SUMPRODUCT(--ISNUMBER(MATCH(TRIM(C10:L10),Extracted_Parameters!$B:$B,0)))=COUNTA(C10:K10)} -> FALSE | O10: {=COUNTA(C10:K10)-SUMPRODUCT(--ISNUMBER(MATCH(C10:K10,Extracted_Parameters!$B:$B,0)))} -> 4 | R10: 4 | S10: =COUNTIF($O$2:$O$260,R10) -> 13 | T10: =(S10/COUNT($O$2:$O$260))*100 -> 5.4852321
B11: 3/1 PhaseCONN | C11: Width | D11: Assembly Drawing | E11: Density | F11: Material | G11: Amperage | H11: Device | N11: {=SUMPRODUCT(--ISNUMBER(MATCH(TRIM(C11:L11),Extracted_Parameters!$B:$B,0)))=COUNTA(C11:K11)} -> FALSE | O11: {=COUNTA(C11:K11)-SUMPRODUCT(--ISNUMBER(MATCH(C11:K11,Extracted_Parameters!$B:$B,0)))} -> 3 | R11: 5 | S11: =COUNTIF($O$2:$O$260,R11) -> 4 | T11: =(S11/COUNT($O$2:$O$260))*100 -> 1.6877637
A12: Bus-Cross, Top Position | B12: AUXILCB | C12: Amperage | D12: Width (Wide) | E12: Heat Test/Density | F12: Assembly No. | G12: 3/1/ Neutral 3/1 Phase Cross Bus | N12: {=SUMPRODUCT(--ISNUMBER(MATCH(TRIM(C12:L12),Extracted_Parameters!$B:$B,0)))=COUNTA(C12:K12)} -> FALSE | O12: {=COUNTA(C12:K12)-SUMPRODUCT(--ISNUMBER(MATCH(C12:K12,Extracted_Parameters!$B:$B,0)))} -> 1 | R12: 6 | S12: =COUNTIF($O$2:$O$260,R12) -> 0 | T12: =(S12/COUNT($O$2:$O$260))*100 -> 0
B13: AUXMACB | C13: DWG Number | D13: Width (Wide) | E13: Heat Test/Density | F13: Material | G13: Amperage | H13: Bus Hole Center | I13: 3/1 Phase | N13: {=SUMPRODUCT(--ISNUMBER(MATCH(TRIM(C13:L13),Extracted_Parameters!$B:$B,0)))=COUNTA(C13:K13)} -> FALSE | O13: {=COUNTA(C13:K13)-SUMPRODUCT(--ISNUMBER(MATCH(C13:K13,Extracted_Parameters!$B:$B,0)))} -> 2
A14: Bus, Cross Bus, Distribution/Individual Device | B14: MAINCB | C14: DWG No. | D14: Bus Hole Center | E14: Amperage | F14: Heat Test/Density | G14: Width (Wide) | H14: Material | I14: Mounting/Non-Mounting Assemblies | N14: {=SUMPRODUCT(--ISNUMBER(MATCH(TRIM(C14:L14),Extracted_Parameters!$B:$B,0)))=COUNTA(C14:K14)} -> FALSE | O14: {=COUNTA(C14:K14)-SUMPRODUCT(--ISNUMBER(MATCH(C14:K14,Extracted_Parameters!$B:$B,0)))} -> 3
B15: DISTCB | C15: Amperage | D15: Width (Wide) | E15: Heat Test/Density | F15: Material | G15: Assembly No. | N15: {=SUMPRODUCT(--ISNUMBER(MATCH(TRIM(C15:L15),Extracted_Parameters!$B:$B,0)))=COUNTA(C15:K15)} -> TRUE | O15: {=COUNTA(C15:K15)-SUMPRODUCT(--ISNUMBER(MATCH(C15:K15,Extracted_Parameters!$B:$B,0)))} -> 0
A16: Bus- Cross Bus Reference Information | B16: BUSCENTE | C16: Bus Rating | D16: Device Centers | E16: X-Bus Centers | F16: Width (Wide) | G16: Device | N16: {=SUMPRODUCT(--ISNUMBER(MATCH(TRIM(C16:L16),Extracted_Parameters!$B:$B,0)))=COUNTA(C16:K16)} -> FALSE | O16: {=COUNTA(C16:K16)-SUMPRODUCT(--ISNUMBER(MATCH(C16:K16,Extracted_Parameters!$B:$B,0)))} -> 4
B17: SWBDBUS | C17: - | N17: {=SUMPRODUCT(--ISNUMBER(MATCH(TRIM(C17:L17),Extracted_Parameters!$B:$B,0)))=COUNTA(C17:K17)} -> FALSE | O17: {=COUNTA(C17:K17)-SUMPRODUCT(--ISNUMBER(MATCH(C17:K17,Extracted_Parameters!$B:$B,0)))} -> 1
A18: Bus- Generic, Crossbus, Runbacks, Connectors- RD, Magnum, Pringle | B18: GENRISERS | C18: Amperage | D18: Material | E18: Heat Test/Density | F18: 3/1 Phase | G18: Bus Centers | N18: {=SUMPRODUCT(--ISNUMBER(MATCH(TRIM(C18:L18),Extracted_Parameters!$B:$B,0)))=COUNTA(C18:K18)} -> FALSE | O18: {=COUNTA(C18:K18)-SUMPRODUCT(--ISNUMBER(MATCH(C18:K18,Extracted_Parameters!$B:$B,0)))} -> 1
B19: GENXBUS | C19: Bus Centers | D19: Amperage | E19: Heat Test/Density | F19: Material | N19: {=SUMPRODUCT(--ISNUMBER(MATCH(TRIM(C19:L19),Extracted_Parameters!$B:$B,0)))=COUNTA(C19:K19)} -> FALSE | O19: {=COUNTA(C19:K19)-SUMPRODUCT(--ISNUMBER(MATCH(C19:K19,Extracted_Parameters!$B:$B,0)))} -> 1
B20: GENDCLMTA | C20: Bus Centers | D20: Heat Test/Density | E20: Material | F20: 3/1 Phase | G20: Device Type | H20: Amperage | N20: {=SUMPRODUCT(--ISNUMBER(MATCH(TRIM(C20:L20),Extracted_Parameters!$B:$B,0)))=COUNTA(C20:K20)} -> FALSE | O20: {=COUNTA(C20:K20)-SUMPRODUCT(--ISNUMBER(MATCH(C20:K20,Extracted_Parameters!$B:$B,0)))} -> 3
B21: GENDCLMBS | C21: Device Type | D21: Bus Center | E21: Family Numbers/ Assembly no. | F21: Heat Test/Density | G21: Material | H21: 3/1 Phase | N21: {=SUMPRODUCT(--ISNUMBER(MATCH(TRIM(C21:L21),Extracted_Parameters!$B:$B,0)))=COUNTA(C21:K21)} -> FALSE | O21: {=COUNTA(C21:K21)-SUMPRODUCT(--ISNUMBER(MATCH(C21:K21,Extracted_Parameters!$B:$B,0)))} -> 3
B22: GENDCUMTA | C22: Device Type | D22: Bus Center | E22: Family Numbers/ Assembly no. | F22: Heat Test/Density | G22: Material | H22: 3/1 Phase | N22: {=SUMPRODUCT(--ISNUMBER(MATCH(TRIM(C22:L22),Extracted_Parameters!$B:$B,0)))=COUNTA(C22:K22)} -> FALSE | O22: {=COUNTA(C22:K22)-SUMPRODUCT(--ISNUMBER(MATCH(C22:K22,Extracted_Parameters!$B:$B,0)))} -> 3
B23: GENDCUMTS | C23: Device Type | D23: Bus Center | E23: Family Numbers/ Assembly no. | F23: Heat Test/Density | G23: Material | H23: 3/1 Phase | N23: {=SUMPRODUCT(--ISNUMBER(MATCH(TRIM(C23:L23),Extracted_Parameters!$B:$B,0)))=COUNTA(C23:K23)} -> FALSE | O23: {=COUNTA(C23:K23)-SUMPRODUCT(--ISNUMBER(MATCH(C23:K23,Extracted_Parameters!$B:$B,0)))} -> 3
B24: GENDRLMTA | C24: Device Type | D24: Bus Center | E24: Family Numbers/ Assembly no. | F24: Heat Test/Density | G24: Material | H24: 3/1 Phase | N24: {=SUMPRODUCT(--ISNUMBER(MATCH(TRIM(C24:L24),Extracted_Parameters!$B:$B,0)))=COUNTA(C24:K24)} -> FALSE | O24: {=COUNTA(C24:K24)-SUMPRODUCT(--ISNUMBER(MATCH(C24:K24,Extracted_Parameters!$B:$B,0)))} -> 3
B25: GENDRLMBS | C25: Device Type | D25: Bus Center | E25: Family Numbers/ Assembly no. | F25: Heat Test/Density | G25: Material | H25: 3/1 Phase | N25: {=SUMPRODUCT(--ISNUMBER(MATCH(TRIM(C25:L25),Extracted_Parameters!$B:$B,0)))=COUNTA(C25:K25)} -> FALSE | O25: {=COUNTA(C25:K25)-SUMPRODUCT(--ISNUMBER(MATCH(C25:K25,Extracted_Parameters!$B:$B,0)))} -> 3
B26: GENDRUMTA | C26: Device Type | D26: Bus Center | E26: Family Numbers/ Assembly no. | F26: Heat Test/Density | G26: Material | H26: 3/1 Phase | N26: {=SUMPRODUCT(--ISNUMBER(MATCH(TRIM(C26:L26),Extracted_Parameters!$B:$B,0)))=COUNTA(C26:K26)} -> FALSE | O26: {=COUNTA(C26:K26)-SUMPRODUCT(--ISNUMBER(MATCH(C26:K26,Extracted_Parameters!$B:$B,0)))} -> 3
B27: GENDRUMTS | C27: Device Type | D27: Bus Center | E27: Family Numbers/ Assembly no. | F27: Heat Test/Density | G27: Material | H27: 3/1 Phase | N27: {=SUMPRODUCT(--ISNUMBER(MATCH(TRIM(C27:L27),Extracted_Parameters!$B:$B,0)))=COUNTA(C27:K27)} -> FALSE | O27: {=COUNTA(C27:K27)-SUMPRODUCT(--ISNUMBER(MATCH(C27:K27,Extracted_Parameters!$B:$B,0)))} -> 3
B28: GENNEUTRALXBUS | C28: Width (Wide) | D28: Amperage | E28: Heat Test/Density | F28: Material | G28: Assembly No. | N28: {=SUMPRODUCT(--ISNUMBER(MATCH(TRIM(C28:L28),Extracted_Parameters!$B:$B,0)))=COUNTA(C28:K28)} -> TRUE | O28: {=COUNTA(C28:K28)-SUMPRODUCT(--ISNUMBER(MATCH(C28:K28,Extracted_Parameters!$B:$B,0)))} -> 0
B29: GENNEUTLUGPADS | C29: Device Type | D29: Width (Wide) | E29: Bus Center | F29: Disconnect | G29: Assembly No. | H29: Heat Test/Density | I29: Material | J29: Service/Non-Service Entrance | N29: {=SUMPRODUCT(--ISNUMBER(MATCH(TRIM(C29:L29),Extracted_Parameters!$B:$B,0)))=COUNTA(C29:K29)} -> FALSE | O29: {=COUNTA(C29:K29)-SUMPRODUCT(--ISNUMBER(MATCH(C29:K29,Extracted_Parameters!$B:$B,0)))} -> 4
A30: Bus Ground | B30: GNDBUS | C30: Bus Rating | D30: Width (Wide) | E30: Amperage | F30: Material | G30: Assembly No. | H30: Utility | N30: {=SUMPRODUCT(--ISNUMBER(MATCH(TRIM(C30:L30),Extracted_Parameters!$B:$B,0)))=COUNTA(C30:K30)} -> FALSE | O30: {=COUNTA(C30:K30)-SUMPRODUCT(--ISNUMBER(MATCH(C30:K30,Extracted_Parameters!$B:$B,0)))} -> 2
B31: GNBUSPLI | C31: Amperage | D31: Bus Capacity | E31: Material | F31: Assembly No. | G31: Offset/ Gnd Bus Splices | N31: {=SUMPRODUCT(--ISNUMBER(MATCH(TRIM(C31:L31),Extracted_Parameters!$B:$B,0)))=COUNTA(C31:K31)} -> FALSE | O31: {=COUNTA(C31:K31)-SUMPRODUCT(--ISNUMBER(MATCH(C31:K31,Extracted_Parameters!$B:$B,0)))} -> 1
A32: Bus Ground (For Cable Pull Sections & Generic Neutral Cross Bus) | B32: GND BOND | C32: Amperage | D32: Assembly No. | E32: Material | N32: {=SUMPRODUCT(--ISNUMBER(MATCH(TRIM(C32:L32),Extracted_Parameters!$B:$B,0)))=COUNTA(C32:K32)} -> TRUE | O32: {=COUNTA(C32:K32)-SUMPRODUCT(--ISNUMBER(MATCH(C32:K32,Extracted_Parameters!$B:$B,0)))} -> 0
A33: Bus- Neutral, Distribution Section | B33: DISECNEU-1 | C33: Riser Amperage Rating | D33: Assembly No. | E33: Heat Test/Density | F33: Material | G33: Width (Wide) | H33: Cross Neut Rating | N33: {=SUMPRODUCT(--ISNUMBER(MATCH(TRIM(C33:L33),Extracted_Parameters!$B:$B,0)))=COUNTA(C33:K33)} -> FALSE | O33: {=COUNTA(C33:K33)-SUMPRODUCT(--ISNUMBER(MATCH(C33:K33,Extracted_Parameters!$B:$B,0)))} -> 2
B34: FAFANEU | C34: Ameperage | D34: Width (Wide) | E34: Heat Test/Density | F34: Material | G34: Assembly No. | H34: Neutral Lugs | N34: {=SUMPRODUCT(--ISNUMBER(MATCH(TRIM(C34:L34),Extracted_Parameters!$B:$B,0)))=COUNTA(C34:K34)} -> FALSE | O34: {=COUNTA(C34:K34)-SUMPRODUCT(--ISNUMBER(MATCH(C34:K34,Extracted_Parameters!$B:$B,0)))} -> 2
B35: NEUGFS | C35: Assembly No. | D35: Material | E35: X-Bus/Chassis Amperage | N35: {=SUMPRODUCT(--ISNUMBER(MATCH(TRIM(C35:L35),Extracted_Parameters!$B:$B,0)))=COUNTA(C35:K35)} -> FALSE | O35: {=COUNTA(C35:K35)-SUMPRODUCT(--ISNUMBER(MATCH(C35:K35,Extracted_Parameters!$B:$B,0)))} -> 1
A36: Bus - Neutral, Individual Mount Section | B36: MASECNEUT | C36: Riser Amperage Rating | D36: Assembly No. | E36: Width (Wide) | F36: Heat Test/Density | G36: Material | H36: Cross Neut Rating | I36: Device | N36: {=SUMPRODUCT(--ISNUMBER(MATCH(TRIM(C36:L36),Extracted_Parameters!$B:$B,0)))=COUNTA(C36:K36)} -> FALSE | O36: {=COUNTA(C36:K36)-SUMPRODUCT(--ISNUMBER(MATCH(C36:K36,Extracted_Parameters!$B:$B,0)))} -> 3
B37: IMSECNEUT | C37: Breaker Type | D37: Max Breaker Amperage | E37: Assembly No. | F37: Cable Entry | G37: Service Entrance | H37: Ground Fault Protection | I37: Bus Position | J37: Heat Test/Density | K37: Material | L37: Width (Wide) | N37: {=SUMPRODUCT(--ISNUMBER(MATCH(TRIM(C37:L37),Extracted_Parameters!$B:$B,0)))=COUNTA(C37:K37)} -> FALSE | O37: {=COUNTA(C37:K37)-SUMPRODUCT(--ISNUMBER(MATCH(C37:K37,Extracted_Parameters!$B:$B,0)))} -> 5
B38: SELNEUT | C38: Assembly No. | D38: Width (Wide) | E38: Heat Test/Density | F38: Material | G38: Device and Amp Rating | N38: {=SUMPRODUCT(--ISNUMBER(MATCH(TRIM(C38:L38),Extracted_Parameters!$B:$B,0)))=COUNTA(C38:K38)} -> FALSE | O38: {=COUNTA(C38:K38)-SUMPRODUCT(--ISNUMBER(MATCH(C38:K38,Extracted_Parameters!$B:$B,0)))} -> 1
B39: RVMNNEUT | C39: Assembly No. | D39: Width (Wide) | E39: Heat Test/Density | F39: Amperage | N39: {=SUMPRODUCT(--ISNUMBER(MATCH(TRIM(C39:L39),Extracted_Parameters!$B:$B,0)))=COUNTA(C39:K39)} -> TRUE | O39: {=COUNTA(C39:K39)-SUMPRODUCT(--ISNUMBER(MATCH(C39:K39,Extracted_Parameters!$B:$B,0)))} -> 0
A40: Bus -Splice, Cross Bus | B40: BUSSPLIC | C40: Assembly No. | D40: Material | E40: Bus Size | F40: Splice Offset | G40: Heat Test/Density | N40: {=SUMPRODUCT(--ISNUMBER(MATCH(TRIM(C40:L40),Extracted_Parameters!$B:$B,0)))=COUNTA(C40:K40)} -> FALSE | O40: {=COUNTA(C40:K40)-SUMPRODUCT(--ISNUMBER(MATCH(C40:K40,Extracted_Parameters!$B:$B,0)))} -> 2
...

Sheet Sheet1
A1: Name | B1: Code | C1: Parameter 1 | D1: Parameter 2 | E1: Parameter 3 | F1: Parameter 4 | G1: Parameter 5
A2: Bus Ground (For Cable Pull Sections & Generic Neutral Cross Bus) | B2: GND BOND | C2: Amperage | D2: Assembly No. | E2: Material
A3: Bus Splice Cross Bus | B3: BUSSPSI | C3: Depth | D3: Bus position
A4: NRX Breaker (3000A Max.), Mounting Assembly, Cross bus, line & Load Connections, Neutral and CAT Numbers | B4: 4 HIGH NRX-RF -D.O. | C4: Part Name | D4: Assembly No. | E4: Depth
A5: Structures- Type 1 & 3R Covers, Barriers, Door Extensions, Doors, Lifting Angles | B5: LFTASSY | C5: Assembly No. | D5: Amperage | E5: Material
A6: 400- 1000A Compartment | B6: WCVTBAR1 | C6: Utility Name | D6: Depth
A7: 400- 1000A Compartment | B7: NEUTBARR-1 | C7: Amperage | D7: Material | E7: Heat Test/Density | F7: Assembly No.
A8: 400- 1000A Compartment | B8: WCLDNEUT | C8: Amperage | D8: Assembly No. | E8: Depth | F8: Material | G8: Heat Test/Density
A9: 1200-5000 A Compartment | B9: WCAUXNT1 | C9: Amperage | D9: Depth | E9: Material | F9: Heat Test/Density | G9: Assembly No.
A10: Utilities- Special Metering Components | B10: CTWISPUB | C10: Amperage | D10: Assembly No. | E10: Heat Test/Density | F10: Material
